<?xml version="1.0"?>
<robot name="puzzlebot">

  <!-- Chassis -->
  <link name="chassis">
    <visual>
      <origin xyz="0 0 0.05" rpy="-1.5707 0 -1.5707"/>
      <geometry>
        <mesh filename="package://puzzlebot_sim/meshes/chassis.stl"/>
      </geometry>
    </visual>
    <collision>
      <origin xyz="-0.055 0 0" rpy="0 0 0"/>
      <geometry>
        <box size="0.2 0.16 0.046"/>
      </geometry>
    </collision>
    <inertial>
      <mass value="0.8"/>
      <origin xyz="-0.05 0 0"/>
      <inertia ixx="0.004" iyy="0.004" izz="0.004"
               ixy="0" ixz="0" iyz="0"/>
    </inertial>
  </link>

  <!-- Left Wheel -->
  <link name="left_wheel">
    <visual>
      <origin xyz="0 0 0" rpy="1.5707 0 0"/>
      <geometry>
        <mesh filename="package://puzzlebot_sim/meshes/wheel.stl"/>
      </geometry>
    </visual>
    <collision>
      <origin xyz="0 -0.0025 0" rpy="0 0 1.5707"/>
      <geometry>
        <cylinder radius="0.05" length="0.005"/>
      </geometry>
    </collision>
    <inertial>
      <mass value="0.05"/>
      <inertia ixx="0.002" iyy="0.002" izz="0.002"
               ixy="0" ixz="0" iyz="0"/>
    </inertial>
  </link>

  <!-- Right Wheel -->
  <link name="right_wheel">
    <visual>
      <origin xyz="0 0 0" rpy="-1.5707 0 0"/>
      <geometry>
        <mesh filename="package://puzzlebot_sim/meshes/wheel.stl"/>
      </geometry>
    </visual>
    <collision>
      <origin xyz="0 -0.0025 0" rpy="1.5707 0 0"/>
      <geometry>
        <cylinder radius="0.05" length="0.005"/>
      </geometry>
    </collision>
    <inertial>
      <mass value="0.05"/>
      <inertia ixx="0.002" iyy="0.002" izz="0.002"
               ixy="0" ixz="0" iyz="0"/>
    </inertial>
  </link>

  <!-- Caster Wheel -->
  <link name="caster">
    <visual>
      <origin xyz="0 0 0" rpy="0 0 0"/>
      <geometry>
        <sphere radius="0.006"/>
      </geometry>
      <material name="green">
        <color rgba="0.0 1.0 0.0 1.0"/>
      </material>
    </visual>
    <collision>
      <geometry>
        <sphere radius="0.006"/>
      </geometry>
    </collision>
    <inertial>
      <mass value="0.01"/>
      <inertia ixx="0.0000025" iyy="0.0000025" izz="0.0000025"
               ixy="0" ixz="0" iyz="0"/>
    </inertial>
  </link>


  <joint name="caster_joint" type="fixed">
    <origin xyz="-0.145 0 -0.044" rpy="0 0 0"/>
    <parent link="chassis"/>
    <child link="caster"/>
  </joint>

<!-- Left Wheel Joint -->
<joint name="left_wheel_joint" type="continuous">
  <origin xyz="0 0.095 0" rpy="0 0 0"/>
  <parent link="chassis"/>
  <child link="left_wheel"/>
  <axis xyz="0 1 0"/>
</joint>

<!-- Right Wheel Joint -->
<joint name="right_wheel_joint" type="continuous">
  <origin xyz="0 -0.095 0" rpy="0 0 0"/>
  <parent link="chassis"/>
  <child link="right_wheel"/>
  <axis xyz="0 1 0"/>
</joint>


</robot>
